#VRML_SIM R2022b utf8

EXTERNPROTO "https://raw.githubusercontent.com/cyberbotics/webots/R2022b/projects/objects/backgrounds/protos/TexturedBackground.proto"
EXTERNPROTO "https://raw.githubusercontent.com/cyberbotics/webots/R2022b/projects/objects/backgrounds/protos/TexturedBackgroundLight.proto"
EXTERNPROTO "https://raw.githubusercontent.com/cyberbotics/webots/R2022b/projects/objects/floors/protos/RectangleArena.proto"
EXTERNPROTO "https://raw.githubusercontent.com/cyberbotics/webots/R2022b/projects/objects/trees/protos/Tree.proto"
EXTERNPROTO "../protos/PottedTree.proto"
EXTERNPROTO "https://raw.githubusercontent.com/cyberbotics/webots/R2022b/projects/objects/drinks/protos/Can.proto"

WorldInfo {
}
Viewpoint {
  orientation 0.4126608053278212 0.010786304155359106 -0.9108209019279598 3.0939799437365294
  position 5.9107416998242925 1.977983764411351 4.346527810867722
  follow "rectangle arena"
}
TexturedBackground {
}
Tree {
}
PottedTree {
  translation 1.809998712342135 -0.5700151306348962 -0.01284575973274682
  rotation 9.555937023776307e-10 -2.526456977742921e-10 0.9999999999999999 1.2332104958531275e-05
  physics Physics {
    mass 20
  }
}
PottedTree {
  translation 1.4799968369216427 -1.8800093788693595 -0.012845759732746487
  rotation -8.248402617294628e-13 -1.0868357953700868e-12 0.9999999999999999 1.511654125344607e-05
  name "potted tree(1)"
  physics Physics {
    mass 20
  }
}
PottedTree {
  translation 0.33998107626598234 -1.8799981105072603 -0.01284575973274682
  rotation -1.2993622290502504e-12 -3.207985987738013e-12 0.9999999999999999 1.01428201947909e-05
  name "potted tree(2)"
  physics Physics {
    mass 20
  }
}
PottedTree {
  translation -0.37 -0.8999999999999999 -0.01284575973274682
  rotation 0.4027250907051716 0.09459427749689085 0.9104199162921209 2.0574134942910222e-16
  name "potted tree(3)"
  physics Physics {
    mass 20
  }
}
PottedTree {
  translation -1.7400105377570954 -0.9000025877187383 -0.01284575973274682
  rotation -3.61749923314468e-11 3.0850877196321817e-11 0.9999999999999999 1.9945781201109944e-05
  name "potted tree(4)"
  physics Physics {
    mass 20
  }
}
PottedTree {
  translation -1.7400005845553865 0.5300108915723843 -0.01284575973274682
  rotation 9.150195288273831e-11 -9.812789257622795e-12 1 2.1884803712200585e-05
  name "potted tree(6)"
  physics Physics {
    mass 20
  }
}
PottedTree {
  translation -0.68 1.45 -0.01284575973274682
  rotation 0.04833139026978066 0.030816450361507347 0.9983558599526058 2.528366601267604e-16
  name "potted tree(7)"
  physics Physics {
    mass 20
  }
}
PottedTree {
  translation 0.3973293886502243 2.2391996972731643 -0.01284575973274693
  rotation -8.261555328296299e-09 7.259566520743185e-07 0.9999999999997364 0.005051439246343943
  name "potted tree(8)"
  physics Physics {
    mass 20
  }
}
PottedTree {
  translation -1.74 -2.18 -0.01284575973274682
  rotation -0.697902224796837 0.3150938514687404 -0.6431549963968409 1.5374230714347375e-17
  name "potted tree(5)"
  physics Physics {
    mass 20
  }
}
TexturedBackgroundLight {
}
RectangleArena {
  floorSize 5 5
}
Robot {
  translation 1.989860374561858 1.5439705129327894 -0.0036538242341782323
  rotation -0.00028536277261730867 0.0003352163160905005 -0.9999999030990502 1.5664195439405515
  children [
    Solid {
      translation 0 0 0.25
      children [
        HingeJoint {
          jointParameters HingeJointParameters {
            anchor 0 -0.05 0.08
          }
          device [
            RotationalMotor {
            }
          ]
          endPoint Solid {
            translation 0 -0.05 0.08
            rotation 0 1 0 0
            children [
              Camera {
                translation 0 -0.01 0
                rotation 0.0006661248411891356 0.000764752426568663 0.9999994857155788 -1.5700384110396213
                name "cam"
                width 720
                height 720
                recognition Recognition {
                  segmentation TRUE
                }
              }
              Shape {
                appearance PBRAppearance {
                  baseColor 0.388235 0.270588 0.172549
                  metalness 0
                }
                geometry Cylinder {
                  height 0.05
                  radius 0.02
                }
              }
            ]
          }
        }
        Solid {
          children [
            Shape {
              appearance PBRAppearance {
                baseColor 0.505882 0.239216 0.611765
                metalness 0
              }
              geometry Box {
                size 0.05 0.05 0.2
              }
            }
          ]
          name "mount_pole"
        }
      ]
      name "camera_mount"
      physics Physics {
      }
    }
    DistanceSensor {
      translation -0.05 -0.25 0.1
      rotation 0 0 -1 1.79
      children [
        DEF SENSOR_LEFT Shape {
          appearance PBRAppearance {
            baseColor 0.752941 0.109804 0.156863
            metalness 0
          }
          geometry Box {
            size 0.01 0.01 0.01
          }
        }
      ]
      name "ds_left"
      boundingObject Shape {
        appearance PBRAppearance {
          baseColor 0.752941 0.109804 0.156863
          metalness 0
        }
        geometry Box {
          size 0.01 0.01 0.01
        }
      }
      physics Physics {
      }
      lookupTable [
        0 0 0
        0.3 1000 0
      ]
    }
    DistanceSensor {
      translation 0.05 -0.25 0.1
      rotation 0 0 -1 1.35
      children [
        Shape {
          appearance PBRAppearance {
            baseColor 0.752941 0.109804 0.156863
            metalness 0
          }
          geometry Box {
            size 0.01 0.01 0.01
          }
        }
      ]
      name "ds_right"
      boundingObject Shape {
        appearance PBRAppearance {
          baseColor 0.647059 0.113725 0.176471
          metalness 0
        }
        geometry Box {
          size 0.01 0.01 0.01
        }
      }
      physics Physics {
      }
      lookupTable [
        0 0 0
        0.3 1000 0
      ]
    }
    HingeJoint {
      jointParameters HingeJointParameters {
        position 254.36811645781805
        anchor -0.125 -0.15 0.1
      }
      device [
        RotationalMotor {
          name "wheel4"
        }
      ]
      endPoint Solid {
        translation -0.12499909138917764 -0.14995692316725595 0.09998090810912214
        rotation 0.7067357049611513 0.037115472838299274 0.7065034217957149 3.0677440002575076
        children [
          DEF WHEEL_4 Shape {
            appearance PBRAppearance {
              baseColor 1 0 1
              metalness 0
            }
            geometry Cylinder {
              height 0.05
              radius 0.1
            }
          }
        ]
        name "wheel4_end"
        boundingObject USE WHEEL_4
        physics Physics {
        }
      }
    }
    HingeJoint {
      jointParameters HingeJointParameters {
        position 1084.8327662844779
        anchor 0.125 -0.15 0.1
      }
      device [
        RotationalMotor {
          name "wheel3"
        }
      ]
      endPoint Solid {
        translation 0.12500007947835795 -0.15001306664384706 0.10000868355139207
        rotation 0.661581277483142 -0.35400134896474245 0.661054655996701 3.822563898042787
        children [
          DEF WHEEL_3 Shape {
            appearance PBRAppearance {
              baseColor 1 0 1
              metalness 0
            }
            geometry Cylinder {
              height 0.05
              radius 0.1
            }
          }
        ]
        name "wheel3_end"
        boundingObject USE WHEEL_3
        physics Physics {
        }
      }
    }
    HingeJoint {
      jointParameters HingeJointParameters {
        position 253.88738338373
        anchor -0.125 0.15 0.1
      }
      device [
        RotationalMotor {
          name "wheel2"
        }
      ]
      endPoint Solid {
        translation -0.12499992098974712 0.15000860725420878 0.1000131183635258
        rotation 0.6920714931637981 0.2069693365001872 0.6915206013552332 2.733100898692465
        children [
          DEF WHEEL_2 Shape {
            appearance PBRAppearance {
              baseColor 1 0 1
              metalness 0
            }
            geometry Cylinder {
              height 0.05
              radius 0.1
            }
          }
        ]
        name "wheel2_end"
        boundingObject USE WHEEL_2
        physics Physics {
        }
      }
    }
    HingeJoint {
      jointParameters HingeJointParameters {
        position 1084.0594630227504
        anchor 0.125 0.15 0.1
      }
      device [
        RotationalMotor {
          name "wheel1"
        }
      ]
      endPoint Solid {
        translation 0.12500007950303915 0.14999671435064135 0.10001534357987625
        rotation 0.7054338478610457 -0.07428391090714533 0.704872319553193 3.2900058106962633
        children [
          DEF WHEEL_1 Shape {
            appearance PBRAppearance {
              baseColor 1 0 1
              metalness 0
            }
            geometry Cylinder {
              height 0.05
              radius 0.1
            }
          }
        ]
        name "wheel1_end"
        boundingObject USE WHEEL_1
        physics Physics {
        }
      }
    }
    Solid {
      translation 0 0 0.1
      children [
        DEF BODY Shape {
          appearance PBRAppearance {
            baseColor 0 1 0
            metalness 0
          }
          geometry Box {
            size 0.2 0.5 0.1
          }
        }
      ]
      name "body"
      boundingObject USE BODY
      physics Physics {
      }
    }
  ]
  physics Physics {
  }
  controller "robot_controller"
}
Can {
  translation 1.23 1.76 0.06096270147991174
  rotation -0.05454448099231833 -0.7578570729456865 -0.650136567637504 1.243621290408278e-16
}
Can {
  translation 1.23 1.27 0.06096270147991175
  rotation -0.037480195679101096 -0.9644468043679734 -0.2616058035982008 9.049136031352476e-17
  name "can(1)"
}
Can {
  translation 0.1 1.31 0.06096270147991175
  rotation -0.5783869794028117 0.30600923919344664 -0.7561923350481276 8.209533785559733e-17
  name "can(2)"
}
Can {
  translation 0.009999999999999993 0.79 0.06096270147991174
  rotation -0.5253429499866363 0.3915880034874348 -0.7554294278250373 2.001371687747206e-16
  name "can(3)"
}
