#VRML_SIM R2022b utf8

EXTERNPROTO "https://raw.githubusercontent.com/cyberbotics/webots/R2022b/projects/objects/backgrounds/protos/TexturedBackground.proto"
EXTERNPROTO "https://raw.githubusercontent.com/cyberbotics/webots/R2022b/projects/objects/backgrounds/protos/TexturedBackgroundLight.proto"
EXTERNPROTO "https://raw.githubusercontent.com/cyberbotics/webots/R2022b/projects/objects/floors/protos/RectangleArena.proto"
EXTERNPROTO "https://raw.githubusercontent.com/cyberbotics/webots/R2022b/projects/objects/trees/protos/Tree.proto"
EXTERNPROTO "../protos/PottedTree.proto"
EXTERNPROTO "https://raw.githubusercontent.com/cyberbotics/webots/R2022b/projects/objects/drinks/protos/Can.proto"

WorldInfo {
}
Viewpoint {
  orientation -0.43072962091148265 -0.4566507431523069 0.7784228236941003 4.5215181620855285
  position 3.8403394187726994 6.858096909282557 6.5781401171678295
  follow "rectangle arena"
}
TexturedBackground {
}
Tree {
}
PottedTree {
  hidden linearVelocity_0 -1.4234805435490526e-11 -5.188405529681237e-11 -0.0018783334831010078
  hidden angularVelocity_0 5.944025459321998e-11 -1.630790454321783e-11 -3.0297862956272165e-17
  translation 1.809998712342106 -0.5700151306350025 -0.012619863532793651
  rotation -1.772579899515236e-06 4.863477102964944e-07 0.9999999999983107 1.2332104958556327e-05
  physics Physics {
    mass 20
  }
}
PottedTree {
  hidden linearVelocity_0 -3.663441120286554e-14 -9.701360699652969e-14 -0.0018783334831015926
  hidden angularVelocity_0 1.1115308766742061e-13 -4.198162061315322e-14 1.7680947999937388e-17
  translation 1.4799968369216414 -1.8800093788693613 -0.012619863532793207
  rotation -2.7056058374566076e-09 1.0140355047905852e-09 1 1.5116541253487858e-05
  name "potted tree(1)"
  physics Physics {
    mass 20
  }
}
PottedTree {
  hidden linearVelocity_0 1.0891475847767079e-13 -8.046194877608144e-15 -0.0018783334831010074
  hidden angularVelocity_0 9.211530392414861e-15 1.247737575821924e-13 -1.37716701703617e-17
  translation 0.339981076265982 -1.8799981105072598 -0.012619863532793651
  rotation -3.448631493470749e-10 -4.522284215346044e-09 1 1.014282019480893e-05
  name "potted tree(2)"
  physics Physics {
    mass 20
  }
}
PottedTree {
  hidden linearVelocity_0 2.324080309544947e-17 2.8736426337826863e-17 -0.001878333483101053
  hidden angularVelocity_0 -3.7255936875287606e-17 -4.329777344909272e-19 4.873319975649714e-18
  translation -0.37 -0.8999999999999999 -0.012619863532793651
  rotation 0.3588898551521674 -0.006700999624707737 0.9333558637909154 1.993129584847786e-16
  name "potted tree(3)"
  physics Physics {
    mass 20
  }
}
PottedTree {
  hidden linearVelocity_0 3.451309415393183e-12 2.9443708913309077e-12 -0.0018783334831010525
  hidden angularVelocity_0 -3.3731711526569773e-12 3.953954484561449e-12 -1.485471343690574e-17
  translation -1.7400105377570882 -0.9000025877187325 -0.012619863532793651
  rotation 6.219544277263211e-08 -7.290347319413869e-08 0.9999999999999953 1.9945781201127993e-05
  name "potted tree(4)"
  physics Physics {
    mass 20
  }
}
PottedTree {
  hidden linearVelocity_0 -1.2214163474684733e-12 -8.985535341847659e-12 -0.0018783334831010074
  hidden angularVelocity_0 1.0294159976058065e-11 -1.3993090929587374e-12 8.882229638723707e-18
  translation -1.7400005845553894 0.5300108915723664 -0.012619863532793651
  rotation -1.729839508632811e-07 2.3520578452735878e-08 0.9999999999999849 2.188480371221477e-05
  name "potted tree(6)"
  physics Physics {
    mass 20
  }
}
PottedTree {
  hidden linearVelocity_0 5.4448063309763075e-17 -8.636635939159145e-17 -0.001878333483101053
  hidden angularVelocity_0 1.1176781062586283e-16 6.825981900123263e-17 7.614254196586053e-18
  translation -0.68 1.45 -0.012619863532793651
  rotation 0.021246275634719886 0.01557420951308472 0.9996529596663513 1.963951236335001e-16
  name "potted tree(7)"
  physics Physics {
    mass 20
  }
}
PottedTree {
  hidden linearVelocity_0 1.6158251499047625e-05 2.2470201244579205e-07 -0.0018783333657228943
  hidden angularVelocity_0 -2.574267665051662e-07 1.851147833783515e-05 -4.395721980327959e-17
  translation 0.3973294218187229 2.239199697734416 -0.012619863532110642
  rotation 1.533746075827166e-05 -0.0013477312087135168 0.9999990916922632 0.005051443834588574
  name "potted tree(8)"
  physics Physics {
    mass 20
  }
}
PottedTree {
  hidden linearVelocity_0 -5.0899596516216406e-17 -3.6264114813005806e-17 -0.001878333483101053
  hidden angularVelocity_0 2.794195265646571e-17 -5.331200222919059e-17 -2.1422268164963154e-17
  translation -1.74 -2.18 -0.012619863532793651
  rotation 0.7983546057386455 0.15841765355944096 -0.5809765662542793 1.1199816204224512e-17
  name "potted tree(5)"
  physics Physics {
    mass 20
  }
}
TexturedBackgroundLight {
}
RectangleArena {
  floorSize 5 5
}
Robot {
  translation 2.15173 1.5448 -0.00367266
  rotation 4.123342004332203e-05 9.762119163373576e-05 -0.999999994384954 1.5664834038326207
  children [
    Solid {
      translation 0 0 0.25
      children [
        HingeJoint {
          jointParameters HingeJointParameters {
            anchor 0 -0.05 0.08
          }
          device [
            RotationalMotor {
            }
          ]
          endPoint Solid {
            translation 0 -0.05 0.08
            rotation 0 1 0 0
            children [
              Camera {
                rotation 0.0006661248411891356 0.000764752426568663 0.9999994857155788 -1.5700384110396213
                name "cam"
                fieldOfView 1
                width 720
                height 720
                recognition Recognition {
                  segmentation TRUE
                }
              }
              Shape {
                appearance PBRAppearance {
                  baseColor 0.388235 0.270588 0.172549
                  metalness 0
                }
                geometry Cylinder {
                  height 0.05
                  radius 0.02
                }
              }
            ]
          }
        }
        Solid {
          children [
            Shape {
              appearance PBRAppearance {
                baseColor 0.505882 0.239216 0.611765
                metalness 0
              }
              geometry Box {
                size 0.05 0.05 0.2
              }
            }
          ]
          name "mount_pole"
        }
      ]
      name "camera_mount"
      physics Physics {
      }
    }
    DistanceSensor {
      translation -0.05 -0.25 0.1
      rotation 0 0 -1 1.79
      children [
        DEF SENSOR_LEFT Shape {
          appearance PBRAppearance {
            baseColor 0.752941 0.109804 0.156863
            metalness 0
          }
          geometry Box {
            size 0.01 0.01 0.01
          }
        }
      ]
      name "ds_left"
      boundingObject Shape {
        appearance PBRAppearance {
          baseColor 0.752941 0.109804 0.156863
          metalness 0
        }
        geometry Box {
          size 0.01 0.01 0.01
        }
      }
      physics Physics {
      }
      lookupTable [
        0 0 0
        0.3 1000 0
      ]
    }
    DistanceSensor {
      translation 0.05 -0.25 0.1
      rotation 0 0 -1 1.35
      children [
        Shape {
          appearance PBRAppearance {
            baseColor 0.752941 0.109804 0.156863
            metalness 0
          }
          geometry Box {
            size 0.01 0.01 0.01
          }
        }
      ]
      name "ds_right"
      boundingObject Shape {
        appearance PBRAppearance {
          baseColor 0.647059 0.113725 0.176471
          metalness 0
        }
        geometry Box {
          size 0.01 0.01 0.01
        }
      }
      physics Physics {
      }
      lookupTable [
        0 0 0
        0.3 1000 0
      ]
    }
    HingeJoint {
      jointParameters HingeJointParameters {
        position 246.83849982944204
        anchor -0.125 -0.15 0.1
      }
      device [
        RotationalMotor {
          name "wheel4"
        }
      ]
      endPoint Solid {
        translation -0.12499909138917764 -0.150004367424888 0.09995308476349417
        rotation -0.6153644438843258 -0.49300230452074356 -0.6150409164764327 4.0576494825234155
        children [
          DEF WHEEL_4 Shape {
            appearance PBRAppearance {
              baseColor 1 0 1
              metalness 0
            }
            geometry Cylinder {
              height 0.05
              radius 0.1
            }
          }
        ]
        name "wheel4_end"
        boundingObject USE WHEEL_4
        physics Physics {
        }
      }
    }
    HingeJoint {
      jointParameters HingeJointParameters {
        position 1077.303167346292
        anchor 0.125 -0.15 0.1
      }
      device [
        RotationalMotor {
          name "wheel3"
        }
      ]
      endPoint Solid {
        translation 0.12500007947835795 -0.1499959339657104 0.10001515284169259
        rotation -0.7043145112655917 -0.093121179693597 -0.7037538739596275 3.3274465510951075
        children [
          DEF WHEEL_3 Shape {
            appearance PBRAppearance {
              baseColor 1 0 1
              metalness 0
            }
            geometry Cylinder {
              height 0.05
              radius 0.1
            }
          }
        ]
        name "wheel3_end"
        boundingObject USE WHEEL_3
        physics Physics {
        }
      }
    }
    HingeJoint {
      jointParameters HingeJointParameters {
        position 246.37890510467415
        anchor -0.125 0.15 0.1
      }
      device [
        RotationalMotor {
          name "wheel2"
        }
      ]
      endPoint Solid {
        translation -0.12499992098974712 0.15001525815676836 0.09999634419110995
        rotation -0.5265657203156257 -0.667756188409504 -0.5261465718117881 4.319841309628582
        children [
          DEF WHEEL_2 Shape {
            appearance PBRAppearance {
              baseColor 1 0 1
              metalness 0
            }
            geometry Cylinder {
              height 0.05
              radius 0.1
            }
          }
        ]
        name "wheel2_end"
        boundingObject USE WHEEL_2
        physics Physics {
        }
      }
    }
    HingeJoint {
      jointParameters HingeJointParameters {
        position 1076.551044479017
        anchor 0.125 0.15 0.1
      }
      device [
        RotationalMotor {
          name "wheel1"
        }
      ]
      endPoint Solid {
        translation 0.12500007950303915 0.15001332360550992 0.10000828869539445
        rotation -0.6583345422821778 -0.3658974851553 -0.6578105052331884 3.843639948666786
        children [
          DEF WHEEL_1 Shape {
            appearance PBRAppearance {
              baseColor 1 0 1
              metalness 0
            }
            geometry Cylinder {
              height 0.05
              radius 0.1
            }
          }
        ]
        name "wheel1_end"
        boundingObject USE WHEEL_1
        physics Physics {
        }
      }
    }
    Solid {
      translation 0 0 0.1
      children [
        DEF BODY Shape {
          appearance PBRAppearance {
            baseColor 0 1 0
            metalness 0
          }
          geometry Box {
            size 0.2 0.5 0.1
          }
        }
      ]
      name "body"
      boundingObject USE BODY
      physics Physics {
      }
    }
  ]
  physics Physics {
  }
  controller "robot_controller"
}
Can {
  hidden linearVelocity_0 3.787237805335328e-17 1.660073037299845e-17 -2.8218014431250364e-05
  hidden angularVelocity_0 -4.2395423647616124e-16 6.190572946976947e-16 1.159212062947222e-16
  translation 1.23 1.76 0.060966268816860104
  rotation 0.36930491904988566 -0.3611127585359002 -0.8562776724802242 5.5102984826730927e-17
}
Can {
  hidden linearVelocity_0 2.4448150386973026e-17 -2.2516232850140308e-17 -2.8218014431250364e-05
  hidden angularVelocity_0 2.119771182380816e-16 5.711307033322072e-16 -1.639738559423162e-16
  translation 1.23 1.27 0.060966268816860104
  rotation 0.15583182288044398 0.3022964957724864 -0.940389957210004 1.0882353261083873e-16
  name "can(1)"
}
Can {
  hidden linearVelocity_0 3.918746500963078e-17 -8.254827232972035e-17 -2.8218014431290967e-05
  hidden angularVelocity_0 1.0598855911904025e-15 5.16559458044447e-16 -2.729810301652175e-17
  translation 0.1 1.31 0.0609662688168601
  rotation -0.7402576495848411 0.19804785150092577 -0.6424917592833342 6.872540716829206e-17
  name "can(2)"
}
Can {
  hidden linearVelocity_0 2.980224787731826e-17 -3.982122967447012e-17 -2.8218014431290967e-05
  hidden angularVelocity_0 8.479084729523223e-16 6.500524051986402e-16 -1.606883966625887e-16
  translation 0.009999999999999998 0.79 0.0609662688168601
  rotation -0.0939909632745414 0.6604285448490577 -0.7449831111986901 2.525927644056002e-16
  name "can(3)"
}
