#VRML_SIM R2022b utf8

EXTERNPROTO "https://raw.githubusercontent.com/cyberbotics/webots/R2022b/projects/objects/backgrounds/protos/TexturedBackground.proto"
EXTERNPROTO "https://raw.githubusercontent.com/cyberbotics/webots/R2022b/projects/objects/backgrounds/protos/TexturedBackgroundLight.proto"
EXTERNPROTO "https://raw.githubusercontent.com/cyberbotics/webots/R2022b/projects/objects/floors/protos/RectangleArena.proto"
EXTERNPROTO "https://raw.githubusercontent.com/cyberbotics/webots/R2022b/projects/objects/trees/protos/Tree.proto"
EXTERNPROTO "../protos/PottedTree.proto"
EXTERNPROTO "https://raw.githubusercontent.com/cyberbotics/webots/R2022b/projects/objects/drinks/protos/Can.proto"

WorldInfo {
}
Viewpoint {
  orientation 0.12506141875890173 -0.01240598006579816 -0.9920714355310397 3.3377634760575754
  position 3.1971712908008394 0.8450955749807495 0.2940122403908939
  follow "rectangle arena"
}
TexturedBackground {
}
Tree {
}
PottedTree {
  hidden linearVelocity_0 3.517675693998947e-14 1.2805501066481202e-13 -1.8451960172933373e-05
  hidden angularVelocity_0 -1.4667662347800732e-13 4.0298886977573335e-14 -2.5376690727629014e-17
  translation 1.809998712342135 -0.5700151306348962 -0.01284575973274682
  rotation 9.555937023776307e-10 -2.526456977742921e-10 0.9999999999999999 1.2332104958531275e-05
  physics Physics {
    mass 20
  }
}
PottedTree {
  hidden linearVelocity_0 -9.175951394144328e-17 8.846670524264425e-17 -1.845196017352465e-05
  hidden angularVelocity_0 -1.1176781062586286e-16 -1.1423132079506847e-16 -1.1748405753553963e-17
  translation 1.4799968369216427 -1.8800093788693595 -0.012845759732746487
  rotation -8.248402617294628e-13 -1.0868357953700868e-12 0.9999999999999999 1.511654125344607e-05
  name "potted tree(1)"
  physics Physics {
    mass 20
  }
}
PottedTree {
  hidden linearVelocity_0 -2.4741025250162433e-16 7.023008010752272e-17 -1.8451960172978872e-05
  hidden angularVelocity_0 -5.58839053129314e-17 -3.0444062650406297e-16 -1.0726550186454744e-17
  translation 0.33998107626598234 -1.8799981105072603 -0.01284575973274682
  rotation -1.2993622290502504e-12 -3.207985987738013e-12 0.9999999999999999 1.01428201947909e-05
  name "potted tree(2)"
  physics Physics {
    mass 20
  }
}
PottedTree {
  hidden linearVelocity_0 5.800670513518006e-17 3.772280944707768e-17 -1.845196017297885e-05
  hidden angularVelocity_0 -1.8627968437643815e-17 6.950757832345217e-17 -4.980890142125206e-18
  translation -0.37 -0.8999999999999999 -0.01284575973274682
  rotation 0.4027250907051716 0.09459427749689085 0.9104199162921209 2.0574134942910222e-16
  name "potted tree(3)"
  physics Physics {
    mass 20
  }
}
PottedTree {
  hidden linearVelocity_0 -8.415646456640336e-15 -7.35597340881291e-15 -1.845196017297874e-05
  hidden angularVelocity_0 8.401213765377354e-15 -9.624733273235897e-15 6.32761739000596e-17
  translation -1.7400105377570954 -0.9000025877187383 -0.01284575973274682
  rotation -3.61749923314468e-11 3.0850877196321817e-11 0.9999999999999999 1.9945781201109944e-05
  name "potted tree(4)"
  physics Physics {
    mass 20
  }
}
PottedTree {
  hidden linearVelocity_0 3.0247012759607113e-15 2.2069644831734276e-14 -1.8451960172933326e-05
  hidden angularVelocity_0 -2.5296781138320284e-14 3.475085657082802e-15 -2.285037161733648e-17
  translation -1.7400005845553865 0.5300108915723843 -0.01284575973274682
  rotation 9.150195288273831e-11 -9.812789257622795e-12 1 2.1884803712200585e-05
  name "potted tree(6)"
  physics Physics {
    mass 20
  }
}
PottedTree {
  hidden linearVelocity_0 2.742302523078004e-17 -2.699803878622102e-17 -1.845196017297901e-05
  hidden angularVelocity_0 5.588390531293143e-17 2.696327311692231e-17 4.336328244412598e-18
  translation -0.68 1.45 -0.01284575973274682
  rotation 0.04833139026978066 0.030816450361507347 0.9983558599526058 2.528366601267604e-16
  name "potted tree(7)"
  physics Physics {
    mass 20
  }
}
PottedTree {
  hidden linearVelocity_0 -3.989422377746961e-08 -5.547828933019671e-10 -1.8451960174161435e-05
  hidden angularVelocity_0 6.354846675245792e-10 -4.569745779598424e-08 2.9163328702975342e-18
  translation 0.3973293886502243 2.2391996972731643 -0.01284575973274693
  rotation -8.261555328296299e-09 7.259566520743185e-07 0.9999999999997364 0.005051439246343943
  name "potted tree(8)"
  physics Physics {
    mass 20
  }
}
PottedTree {
  hidden linearVelocity_0 9.83715495465748e-18 5.3563152194469224e-17 -1.8451960172978825e-05
  hidden angularVelocity_0 -5.588390531293143e-17 -1.0238013737493949e-18 -7.489304901334123e-18
  translation -1.74 -2.18 -0.01284575973274682
  rotation -0.697902224796837 0.3150938514687404 -0.6431549963968409 1.5374230714347375e-17
  name "potted tree(5)"
  physics Physics {
    mass 20
  }
}
TexturedBackgroundLight {
}
RectangleArena {
  floorSize 5 5
}
Robot {
  translation 1.989860374561858 1.5439705129327894 -0.0036538242341782323
  rotation -0.00028536277261730867 0.0003352163160905005 -0.9999999030990502 1.5664195439405515
  children [
    Solid {
      translation 0 0 0.25
      children [
        HingeJoint {
          jointParameters HingeJointParameters {
            anchor 0 -0.05 0.08
          }
          device [
            RotationalMotor {
            }
          ]
          endPoint Solid {
            translation 0 -0.05 0.08
            rotation 0 1 0 0
            children [
              Camera {
                translation 0 -0.01 0
                rotation 0.0006661248411891356 0.000764752426568663 0.9999994857155788 -1.5700384110396213
                scale 0.1 0.1 0.1
                name "cam"
                width 720
                height 720
                recognition Recognition {
                  segmentation TRUE
                }
              }
              Shape {
                appearance PBRAppearance {
                  baseColor 0.388235 0.270588 0.172549
                  metalness 0
                }
                geometry Cylinder {
                  height 0.05
                  radius 0.02
                }
              }
            ]
          }
        }
        Solid {
          children [
            Shape {
              appearance PBRAppearance {
                baseColor 0.505882 0.239216 0.611765
                metalness 0
              }
              geometry Box {
                size 0.05 0.05 0.2
              }
            }
          ]
          name "mount_pole"
        }
      ]
      name "camera_mount"
      physics Physics {
      }
    }
    DistanceSensor {
      translation -0.05 -0.25 0.1
      rotation 0 0 -1 1.79
      children [
        DEF SENSOR_LEFT Shape {
          appearance PBRAppearance {
            baseColor 0.752941 0.109804 0.156863
            metalness 0
          }
          geometry Box {
            size 0.01 0.01 0.01
          }
        }
      ]
      name "ds_left"
      boundingObject Shape {
        appearance PBRAppearance {
          baseColor 0.752941 0.109804 0.156863
          metalness 0
        }
        geometry Box {
          size 0.01 0.01 0.01
        }
      }
      physics Physics {
      }
      lookupTable [
        0 0 0
        0.3 1000 0
      ]
    }
    DistanceSensor {
      translation 0.05 -0.25 0.1
      rotation 0 0 -1 1.35
      children [
        Shape {
          appearance PBRAppearance {
            baseColor 0.752941 0.109804 0.156863
            metalness 0
          }
          geometry Box {
            size 0.01 0.01 0.01
          }
        }
      ]
      name "ds_right"
      boundingObject Shape {
        appearance PBRAppearance {
          baseColor 0.647059 0.113725 0.176471
          metalness 0
        }
        geometry Box {
          size 0.01 0.01 0.01
        }
      }
      physics Physics {
      }
      lookupTable [
        0 0 0
        0.3 1000 0
      ]
    }
    HingeJoint {
      jointParameters HingeJointParameters {
        position 254.36811645781805
        anchor -0.125 -0.15 0.1
      }
      device [
        RotationalMotor {
          name "wheel4"
        }
      ]
      endPoint Solid {
        translation -0.12499909138917764 -0.14995692316725595 0.09998090810912214
        rotation 0.7067357049611516 0.037115472838299274 0.7065034217957149 3.0677440002575076
        children [
          DEF WHEEL_4 Shape {
            appearance PBRAppearance {
              baseColor 1 0 1
              metalness 0
            }
            geometry Cylinder {
              height 0.05
              radius 0.1
            }
          }
        ]
        name "wheel4_end"
        boundingObject USE WHEEL_4
        physics Physics {
        }
        linearVelocity -0.10030230066288735 -0.00042656782096939423 -0.00023233745319370185
        angularVelocity 0.004261831873964502 -1.003134645225235 -4.772974802947232e-05
      }
    }
    HingeJoint {
      jointParameters HingeJointParameters {
        position 1084.8327662844779
        anchor 0.125 -0.15 0.1
      }
      device [
        RotationalMotor {
          name "wheel3"
        }
      ]
      endPoint Solid {
        translation 0.12500007947835795 -0.15001306664384706 0.10000868355139207
        rotation 0.6615812774831419 -0.3540013489647425 0.6610546559967009 3.822563898042787
        children [
          DEF WHEEL_3 Shape {
            appearance PBRAppearance {
              baseColor 1 0 1
              metalness 0
            }
            geometry Cylinder {
              height 0.05
              radius 0.1
            }
          }
        ]
        name "wheel3_end"
        boundingObject USE WHEEL_3
        physics Physics {
        }
        linearVelocity -0.10031553078857797 -0.0004266234291516691 -0.0002560724346333602
        angularVelocity 0.00426184125573934 -1.0031372247992536 -4.778969600445406e-05
      }
    }
    HingeJoint {
      jointParameters HingeJointParameters {
        position 253.88738338373
        anchor -0.125 0.15 0.1
      }
      device [
        RotationalMotor {
          name "wheel2"
        }
      ]
      endPoint Solid {
        translation -0.12499992098974712 0.15000860725420878 0.1000131183635258
        rotation 0.6920714931637981 0.20696933650018717 0.6915206013552333 2.733100898692465
        children [
          DEF WHEEL_2 Shape {
            appearance PBRAppearance {
              baseColor 1 0 1
              metalness 0
            }
            geometry Cylinder {
              height 0.05
              radius 0.1
            }
          }
        ]
        name "wheel2_end"
        boundingObject USE WHEEL_2
        physics Physics {
        }
        linearVelocity -0.10031783848392213 -0.00042575745576208 0.0006630135695042563
        angularVelocity 0.004261711849785394 -1.0031376851082703 -4.7948725160194414e-05
      }
    }
    HingeJoint {
      jointParameters HingeJointParameters {
        position 1084.0594630227504
        anchor 0.125 0.15 0.1
      }
      device [
        RotationalMotor {
          name "wheel1"
        }
      ]
      endPoint Solid {
        translation 0.12500007950303915 0.14999671435064135 0.10001534357987625
        rotation 0.7054338478610457 -0.07428391090714533 0.704872319553193 3.2900058106962633
        children [
          DEF WHEEL_1 Shape {
            appearance PBRAppearance {
              baseColor 1 0 1
              metalness 0
            }
            geometry Cylinder {
              height 0.05
              radius 0.1
            }
          }
        ]
        name "wheel1_end"
        boundingObject USE WHEEL_1
        physics Physics {
        }
        linearVelocity -0.1003183520058362 -0.0004257599961023763 0.0006834166313558005
        angularVelocity 0.004261710705479869 -1.0031377840046503 -4.8014030772954e-05
      }
    }
    Solid {
      translation 0 0 0.1
      children [
        DEF BODY Shape {
          appearance PBRAppearance {
            baseColor 0 1 0
            metalness 0
          }
          geometry Box {
            size 0.2 0.5 0.1
          }
        }
      ]
      name "body"
      boundingObject USE BODY
      physics Physics {
      }
    }
  ]
  physics Physics {
  }
  controller "robot_controller"
  linearVelocity -0.10032647317150122 -0.0004256987725455668 0.00010894123527889549
  angularVelocity -0.00011483267650372697 -0.0031464491219608177 6.895493525088309e-06
}
Can {
  hidden linearVelocity_0 5.639957017350773e-17 -8.49349648157754e-17 -3.243391930141139e-07
  hidden angularVelocity_0 1.059885591190403e-15 8.363038451507082e-16 1.273157343263651e-16
  translation 1.23 1.76 0.06096270147991174
  rotation -0.05454448099231833 -0.7578570729456865 -0.650136567637504 1.243621290408278e-16
}
Can {
  hidden linearVelocity_0 -6.055563315717268e-17 -2.9128426603915806e-17 -3.243391930547165e-07
  hidden angularVelocity_0 4.2395423647616143e-16 -1.214107790200557e-15 1.8040787834812634e-17
  translation 1.23 1.27 0.06096270147991175
  rotation -0.037480195679101096 -0.9644468043679734 -0.2616058035982008 9.049136031352476e-17
  name "can(1)"
}
Can {
  hidden linearVelocity_0 6.592706800362101e-17 5.4801269865349915e-17 -3.243391930141124e-07
  hidden angularVelocity_0 -1.2718627094284837e-15 1.3616462166053194e-15 -1.552521329403984e-16
  translation 0.1 1.31 0.06096270147991175
  rotation -0.5783869794028117 0.30600923919344664 -0.7561923350481276 8.209533785559733e-17
  name "can(2)"
}
Can {
  hidden linearVelocity_0 -7.930128693583024e-17 2.4542319713487074e-17 -3.243391930141145e-07
  hidden angularVelocity_0 -4.2395423647616183e-16 -1.1148200488900485e-15 -9.802749592615403e-17
  translation 0.009999999999999993 0.79 0.06096270147991174
  rotation -0.5253429499866363 0.3915880034874348 -0.7554294278250373 2.001371687747206e-16
  name "can(3)"
}
